Workbook
Name prevWBS: Dashboard!$A1048576

Sheet Sheet1
A1: Email | B1: Name | C1: Change Computer Name | D1: Computer Name | E1: Monitor Name 1 | F1: Brand | G1: Model | H1: Service Tag | I1: Monitor Name 2 | J1: Brand1 | K1: Model1 | L1: Service Tag1 | M1: Windows | N1: Windows Activate ? | O1: Windows version (winver) | P1: Office | Q1: Office Activate? | R1: update anti virus ? | S1: IP Phone | T1: Printer Local ? | U1: UPS ? | V1: Install agent GLPI 1.6/1.7 | W1: Install agent spicework | X1: Change password admin local | Y1: Check USB Policy | Z1: PC Audit | AA1: HW info | AB1: Cleaning Device? | AC1: ปัญหาการใช้งาน มีไหม | AD1: Customer Satisfaction | AE1: Staff Service
A2: asawin.ima@trrgroup.com | B2: Asawin Imaromkul | C2: Yes | D2: HQ-PS-N042 | E2: - | F2: - | G2: - | H2: - | I2: - | J2: - | K2: - | L2: - | M2: Windows 10 | N2: Yes | O2: 22H2 | P2: MS 365 | Q2: Yes | R2: Yes | S2: 1843 | T2: No | U2: No | V2: Yes | W2: yes | X2: No | Y2: Yes | Z2: Yes | AA2: Yes | AB2: Yes | AD2: 5 | AE2: วัชระ คิดโสดา (แจ็ค)
A3: phonwimon.aut@trrgroup.com | B3: Phonwimon Authai | C3: No | D3: HQ-PS-N035 | E3: - | F3: - | G3: - | H3: - | I3: - | J3: - | K3: - | L3: - | M3: Windows 11 | N3: Yes | O3: 24H2 (26100.4349) | P3: MS 365 | Q3: Yes | R3: Yes | S3: 1848 | T3: No | U3: No | V3: Yes | W3: yes | X3: No | Y3: No | Z3: Yes | AA3: Yes | AB3: Yes | AD3: 4 | AE3: ชัยวัฒน์ จารุกรุณา (วัฒน์)
A4: audit.ps@trrgroup.com | B4: Audit PS | C4: No | D4: HQ-PS-N033 | E4: - | F4: - | G4: - | H4: - | I4: - | J4: - | K4: - | L4: - | M4: Windows 11 | N4: Yes | O4: 24H2 (26100.4349) | P4: MS 365 | Q4: Yes | R4: Yes | S4: 1849 | T4: No | U4: No | V4: Yes | W4: yes | X4: No | Y4: Yes | Z4: Yes | AA4: Yes | AB4: Yes | AD4: 5 | AE4: วัชระ คิดโสดา (แจ็ค)
A5: watchara.kid@trrgroup.com | B5: Watchara Kidsoda | C5: No | D5: HQ-PS-N013 | E5: - | F5: LG | G5: GSM5AB6 | H5: 607NTVS8N727 | I5: - | J5: - | K5: - | L5: - | M5: Windows 10 | N5: Yes | O5: 22H2 | P5: MS 365 | Q5: Yes | R5: Yes | S5: - | T5: No | U5: No | V5: Yes | W5: yes | X5: No | Y5: Yes | Z5: Yes | AA5: Yes | AB5: Yes | AD5: 5 | AE5: วัชระ คิดโสดา (แจ็ค)
A6: chamaiporn.ker@trrgroup.com | B6: Chamaiporn Kertpunya | C6: No | D6: HQ-TRR-N131 | E6: - | F6: - | G6: - | H6: - | I6: - | J6: - | K6: - | L6: - | M6: Windows 10 | N6: No | O6: 22H2 (19045.5737) | P6: MS 365 | Q6: Yes | R6: Yes | S6: 1218 | T6: No | U6: No | V6: Yes | W6: yes | X6: No | Y6: Yes | Z6: Yes | AA6: Yes | AB6: Yes | AD6: 4 | AE6: ชัยวัฒน์ จารุกรุณา (วัฒน์)
A7: salisa.cha@trrgroup.com | B7: Salisa Chaichompoo | C7: No | D7: HQ-TRR-N128 | E7: - | F7: - | G7: - | H7: - | I7: - | J7: - | K7: - | L7: - | M7: Windows 11 | N7: No | O7: 24H2 (26100.4770) | P7: 2016 | Q7: No | R7: Yes | S7: - | T7: No | U7: No | V7: Yes | W7: yes | X7: No | Y7: Yes | Z7: Yes | AA7: Yes | AB7: Yes | AD7: 5 | AE7: วัชระ คิดโสดา (แจ็ค)
A8: tanatorn.sri@trrgroup.com | B8: Tanatorn Sriwatchirakai | C8: No | D8: HQ-TRR-N149 | E8: - | F8: - | G8: - | H8: - | I8: - | J8: - | K8: - | L8: - | M8: Windows 10 | N8: Yes | O8: 22H2 (19045.5737) | P8: MS 365 | Q8: Yes | R8: Yes | S8: 1877 | T8: Yes | U8: No | V8: No | W8: yes | X8: No | Y8: Yes | Z8: Yes | AA8: Yes | AB8: Yes | AD8: 4 | AE8: ชัยวัฒน์ จารุกรุณา (วัฒน์)
A9: amphorn.hon@trrgroup.com | B9: Amphorn Hongkhammee | C9: No | D9: HQ-PS-N045 | E9: - | F9: - | G9: - | H9: - | I9: - | J9: - | K9: - | L9: - | M9: Windows 11 | N9: Yes | O9: 24H2 (26100.4484) | P9: MS 365 | Q9: Yes | R9: Yes | S9: 1812 | T9: No | U9: No | V9: Yes | W9: yes | X9: No | Y9: Yes | Z9: Yes | AA9: Yes | AB9: Yes | AD9: 5 | AE9: วัชระ คิดโสดา (แจ็ค)
A10: watchara.kid@trrgroup.com | B10: Watchara Kidsoda | C10: No | D10: HQ-PS-N017 | E10: - | F10: - | G10: - | H10: - | I10: - | J10: - | K10: - | L10: - | M10: Windows 10 | N10: Yes | O10: 22H2 (19045.5965) | P10: 2019 | Q10: No | R10: Yes | S10: - | T10: No | U10: No | V10: Yes | W10: yes | X10: Yes | Y10: Yes | Z10: Yes | AA10: Yes | AB10: Yes | AD10: 5 | AE10: วัชระ คิดโสดา (แจ็ค)
A11: wirat.uss@trrgroup.com | B11: Wirat Ussawaprechawong | C11: No | D11: HQ-PS-P010 | E11: - | F11: - | G11: - | H11: - | I11: - | J11: - | K11: - | L11: - | M11: Windows 10 | N11: Yes | O11: 22H2 | P11: MS 365 | Q11: No | R11: Yes | S11: - | T11: No | U11: No | V11: Yes | W11: yes | X11: Yes | Y11: Yes | Z11: Yes | AA11: Yes | AB11: Yes | AD11: 5 | AE11: วัชระ คิดโสดา (แจ็ค)
A12: watchara.kid@trrgroup.com | B12: Watchara Kidsoda | C12: No | D12: HQ-PS-N046 | E12: - | F12: - | G12: - | H12: - | I12: - | J12: - | K12: - | L12: - | M12: Windows 11 | N12: Yes | O12: 24H2 | P12: 2021 | Q12: Yes | R12: Yes | S12: - | T12: No | U12: No | V12: Yes | W12: yes | X12: No | Y12: Yes | Z12: Yes | AA12: Yes | AB12: Yes | AD12: 5 | AE12: วัชระ คิดโสดา (แจ็ค)
A13: krittiya.sin@trrgroup.com | B13: Krittiya Singpolngam | C13: No | D13: HQ-TRRL-N008 | E13: - | F13: - | G13: - | H13: - | I13: - | J13: - | K13: - | L13: - | M13: Windows 11 | N13: Yes | O13: 24H2 (26100.3476) | P13: 2016 | Q13: No | R13: Yes | S13: - | T13: No | U13: No | V13: Yes | W13: yes | X13: No | Y13: Yes | Z13: Yes | AA13: Yes | AB13: Yes | AD13: 5 | AE13: วัชระ คิดโสดา (แจ็ค)
... A32: phadkaphong.pho@trrgroup.com | B32: Phadkaphong Phombut | C32: No | D32: HQ-PS-N014 | E32: HQ-PS-M014 | F32: DELL | G32: S2421H | H32: D2N3YN3 | I32: - | J32: - | K32: - | L32: - | M32: Windows 10 | N32: Yes | O32: 22H2 (19045.5737) | P32: 2016 | Q32: No | R32: Yes | S32: - | T32: No | U32: No | V32: Yes | W32: yes | X32: No | Y32: Yes | Z32: Yes | AA32: Yes | AB32: Yes | AD32: 4 | AE32: ชัยวัฒน์ จารุกรุณา (วัฒน์)
A33: jittakorn.kra@trrgroup.com | B33: Jittakorn Krasobthong | C33: No | D33: HQ-PS-N020 | E33: HQ-PS-M015 | F33: DELL | G33: S2421HN | H33: 7V11D23 | I33: - | J33: - | K33: - | L33: - | M33: Windows 10 | N33: Yes | O33: 22H2 (19045.5854) | P33: MS 365 | Q33: Yes | R33: Yes | S33: 1815 | T33: Yes | U33: No | V33: Yes | W33: yes | X33: Yes | Y33: Yes | Z33: Yes | AA33: Yes | AB33: Yes | AC33: EPSON LQ-2090 S/N FT7Y069990 | AD33: 5 | AE33: วัชระ คิดโสดา (แจ็ค)
A34: piyawan.sae@trrgroup.com | B34: Piyawan Sae-Ung | C34: No | D34: HQ-PS-N037 | E34: HQ-PS-M016 | F34: DELL | G34: E2425HS | H34: FG2ZZ64 | I34: - | J34: - | K34: - | L34: - | M34: Windows 11 | N34: Yes | O34: 24H2 (26100.4061) | P34: 2019 | Q34: Yes | R34: Yes | S34: 1827 | T34: No | U34: No | V34: Yes | W34: yes | X34: No | Y34: Yes | Z34: Yes | AA34: Yes | AB34: Yes | AD34: 5 | AE34: วัชระ คิดโสดา (แจ็ค)
A35: nutipong.cla@trrgroup.com | B35: Nutipong Claisit | C35: No | D35: HQ-PS-N027 | E35: HQ-PS-M017 | F35: DELL | G35: S2421HN | H35: BMMLZG3 | I35: - | J35: - | K35: - | L35: - | M35: Windows 10 | N35: Yes | O35: 22H2 (19045.5854) | P35: MS 365 | Q35: Yes | R35: Yes | S35: 1825 | T35: No | U35: No | V35: Yes | W35: yes | X35: No | Y35: Yes | Z35: Yes | AA35: Yes | AB35: Yes | AD35: 5 | AE35: วัชระ คิดโสดา (แจ็ค)
A36: nitikorn.sor@trrgroup.com | B36: Nitikorn Sornsaard | C36: No | D36: HQ-PS-N044 | E36: HQ-PS-M018 | F36: DELL | G36: E2425HSM | H36: H4XG074 | I36: - | J36: - | K36: - | L36: - | M36: Windows 11 | N36: Yes | O36: 24H2 (26100.4351) | P36: 2019 | Q36: Yes | R36: Yes | S36: - | T36: No | U36: No | V36: Yes | W36: yes | X36: No | Y36: Yes | Z36: Yes | AA36: Yes | AB36: Yes | AD36: 4 | AE36: ชัยวัฒน์ จารุกรุณา (วัฒน์)
A37: wanthanee.saw@trrgroup.com | B37: Wanthanee Sawaddee | C37: No | D37: HQ-PS-N011 | E37: HQ-PS-M019 | F37: DELL | G37: E2422HS | H37: 58ZCWQ3 | I37: - | J37: - | K37: - | L37: - | M37: Windows 10 | N37: Yes | O37: 22H2 (19045.5854) | P37: MS 365 | Q37: Yes | R37: Yes | S37: 1814 | T37: No | U37: No | V37: Yes | W37: yes | X37: No | Y37: Yes | Z37: Yes | AA37: Yes | AB37: Yes | AD37: 5 | AE37: วัชระ คิดโสดา (แจ็ค)
A38: thitamon.dou@trrgroup.com | B38: Thitamon Doungleang | C38: No | D38: HQ-PS-N012 | E38: HQ-PS-M020 | F38: SAMSUNG | G38: S24F350 | H38: H4ZJ701794 | I38: - | J38: - | K38: - | L38: - | M38: Windows 10 | N38: Yes | O38: 22H2 (19045.5965) | P38: MS 365 | Q38: Yes | R38: Yes | S38: 1814 | T38: No | U38: No | V38: Yes | W38: yes | X38: No | Y38: Yes | Z38: Yes | AA38: Yes | AB38: Yes | AD38: 5 | AE38: วัชระ คิดโสดา (แจ็ค)
A39: kerati.num@trrgroup.com | B39: Kerati Numahan | C39: No | D39: HQ-PS-N024 | E39: HQ-PS-M021 | F39: DELL | G39: S2421HN | H39: 27SY2H3 | I39: - | J39: - | K39: - | L39: - | M39: Windows 10 | N39: Yes | O39: 22H2 (19045.5965) | P39: MS 365 | Q39: Yes | R39: Yes | S39: 1880 | T39: No | U39: No | V39: Yes | W39: yes | X39: No | Y39: Yes | Z39: Yes | AA39: Yes | AB39: Yes | AD39: 5 | AE39: วัชระ คิดโสดา (แจ็ค)
A40: nithi.dee@trrgroup.com | B40: Nithi Deejaroon | C40: No | D40: HQ-PS-N005 | E40: HQ-PS-M022 | F40: LG | G40: GSM5AB8 | H40: - | I40: - | J40: - | K40: - | L40: - | M40: Windows 10 | N40: No | O40: 22H2 (19045.5965) | P40: 2016 | Q40: No | R40: Yes | S40: 1817 | T40: No | U40: No | V40: Yes | W40: yes | X40: No | Y40: Yes | Z40: Yes | AA40: Yes | AB40: Yes | AD40: 4 | AE40: ชัยวัฒน์ จารุกรุณา (วัฒน์)
A41: chalita.sim@trrgroup.com | B41: Chalita Simpla | C41: No | D41: HQ-PS-N001 | E41: HQ-PS-M023 | F41: DELL | G41: SE2422H | H41: 262VWY3 | I41: - | J41: - | K41: - | L41: - | M41: Windows 11 | N41: Yes | O41: 23H2 (22631.5472) | P41: MS 365 | Q41: Yes | R41: Yes | S41: 1881 | T41: No | U41: No | V41: Yes | W41: yes | X41: No | Y41: Yes | Z41: Yes | AA41: Yes | AB41: Yes | AD41: 5 | AE41: วัชระ คิดโสดา (แจ็ค)
A42: wirat.uss@trrgroup.com | B42: Wirat Ussawaprechawong | C42: No | D42: HQ-PS-N026 | E42: HQ-PS-M024 | F42: DELL | G42: DEL41F1 | H42: 5S6H623 | I42: - | J42: - | K42: - | L42: - | M42: Windows 10 | N42: Yes | O42: 22H2 (19045.5854) | P42: MS 365 | Q42: Yes | R42: Yes | S42: 1808 | T42: No | U42: No | V42: Yes | W42: yes | X42: No | Y42: Yes | Z42: Yes | AA42: Yes | AB42: Yes | AD42: 4 | AE42: ชัยวัฒน์ จารุกรุณา (วัฒน์)
A43: ariyapat.noi@trrgroup.com | B43: Ariyapat Noiwilai | C43: No | D43: HQ-PS-N025 | E43: HQ-PS-M025 | F43: DELL | G43: S2318H | H43: 4XPPC82Q00KB | I43: - | J43: - | K43: - | L43: - | M43: Windows 10 | N43: Yes | O43: 22H2 (19045.5965) | P43: MS 365 | Q43: Yes | R43: Yes | S43: 1822 | T43: No | U43: No | V43: Yes | W43: yes | X43: No | Y43: Yes | Z43: Yes | AA43: Yes | AB43: Yes | AD43: 5 | AE43: วัชระ คิดโสดา (แจ็ค)
A44: wipada.kae@trrgroup.com | B44: Wipada Kaewmanee | C44: No | D44: HQ-PS-N002 | E44: HQ-PS-M026 | F44: SAMSUNG | G44: S24F350 | H44: H4ZJ900195 | I44: - | J44: - | K44: - | L44: - | M44: Windows 10 | N44: No | O44: 22H2 (19045.5965) | P44: MS 365 | Q44: Yes | R44: Yes | S44: 1819 | T44: No | U44: No | V44: Yes | W44: yes | X44: No | Y44: Yes | Z44: Yes | AA44: Yes | AB44: Yes | AD44: 5 | AE44: วัชระ คิดโสดา (แจ็ค)
A45: thanadee.cha@trrgroup.com | B45: Thanadee Chanvipava | C45: No | D45: HQ-PS-N038 | E45: HQ-PS-M027 | F45: DELL | G45: E2425HSM | H45: 7PG5M84 | I45: - | J45: - | K45: - | L45: - | M45: Windows 11 | N45: Yes | O45: 24H2 (26100.4351) | P45: 2019 | Q45: Yes | R45: Yes | S45: - | T45: No | U45: No | V45: Yes | W45: yes | X45: No | Y45: Yes | Z45: Yes | AA45: Yes | AB45: Yes | AD45: 5 | AE45: วัชระ คิดโสดา (แจ็ค)
... A47: atchara.sua@trrgroup.com | B47: Atchara Suansawan | C47: No | D47: HQ-PS-N032 | E47: HQ-PS-M029 | F47: DELL | G47: SE2419H | H47: JXF4CX2 | I47: - | J47: - | K47: - | L47: - | M47: Windows 10 | N47: Yes | O47: 22H2 (19045.5854) | P47: MS 365 | Q47: Yes | R47: Yes | S47: 1800 | T47: No | U47: No | V47: Yes | W47: yes | X47: No | Y47: Yes | Z47: Yes | AA47: Yes | AB47: Yes | AD47: 4 | AE47: ชัยวัฒน์ จารุกรุณา (วัฒน์)
A48: amphorn.hon@trrgroup.com | B48: Amphorn Hongkhammee | C48: No | D48: HQ-PS-N006 | E48: HQ-PS-M033 | F48: PHILIPS | G48: 246E7 | H48: AU01625011148 | I48: - | J48: - | K48: - | L48: - | M48: Windows 10 | N48: No | O48: 22H2 (19045.5737) | P48: 2016 | Q48: No | R48: Yes | S48: 1812 | T48: Yes | U48: No | V48: Yes | W48: yes | X48: No | Y48: Yes | Z48: Yes | AA48: Yes | AB48: Yes | AC48: 791 OKI 24pin S/N: AK83060568E0 | AD48: 5 | AE48: วัชระ คิดโสดา (แจ็ค)
A49: prapunsak@trrgroup.com | B49: Prapunsak Wongpaitoon | C49: No | D49: HQ-PS-N030 | E49: HQ-PS-M030 | F49: LG | G49: GSM5AB7 | H49: 607NTVS8N727 | I49: - | J49: - | K49: - | L49: - | M49: Windows 10 | N49: Yes | O49: 22H2 (19045.5965) | P49: MS 365 | Q49: Yes | R49: Yes | S49: 1803 | T49: No | U49: No | V49: Yes | W49: yes | X49: No | Y49: Yes | Z49: Yes | AA49: Yes | AB49: Yes | AD49: 5 | AE49: วัชระ คิดโสดา (แจ็ค)
A50: sawanya.mah@trrgroup.com | B50: Sawanya Mahakan | C50: No | D50: HQ-PS-N021 | E50: HQ-PS-M031 | F50: SAMSUNG | G50: S24F350 | H50: H4ZH700996 | I50: - | J50: - | K50: - | L50: - | M50: Windows 10 | N50: Yes | O50: 22H2 (19045.5965) | P50: MS 365 | Q50: Yes | R50: Yes | S50: 1824 | T50: No | U50: No | V50: Yes | W50: yes | X50: No | Y50: Yes | Z50: Yes | AA50: Yes | AB50: Yes | AD50: 4 | AE50: ชัยวัฒน์ จารุกรุณา (วัฒน์)
A51: yutthapol.cha@trrgroup.com | B51: Yutthapol Charoenrat | C51: No | D51: HQ-PS-N034 | E51: HQ-PS-M032 | F51: DELL | G51: S2421HN | H51: 1S6H623 | I51: - | J51: - | K51: - | L51: - | M51: Windows 11 | N51: Yes | O51: 24H2 (26100.4351) | P51: MS 365 | Q51: Yes | R51: Yes | S51: 1847 | T51: No | U51: No | V51: Yes | W51: yes | X51: No | Y51: Yes | Z51: Yes | AA51: Yes | AB51: Yes | AD51: 5 | AE51: วัชระ คิดโสดา (แจ็ค)
A52: benjawan.vae@trrgroup.com | B52: Benjawan Vaenkaew | C52: No | D52: HQ-PS-N029 | E52: HQ-PS-M034 | F52: DELL | G52: S2421HN | H52: 5NMLZG3 | I52: - | J52: - | K52: - | L52: - | M52: Windows 10 | N52: Yes | O52: 22H2 (19045.5737) | P52: MS 365 | Q52: Yes | R52: Yes | S52: 1811 | T52: No | U52: No | V52: Yes | W52: yes | X52: No | Y52: Yes | Z52: Yes | AA52: Yes | AB52: Yes | AD52: 4 | AE52: ชัยวัฒน์ จารุกรุณา (วัฒน์)
A53: thawatchai.pha@trrgroup.com | B53: Thawatchai Phaengphaeng | C53: No | D53: HQ-PS-N022 | E53: HQ-PS-M035 | F53: DELL | G53: S2421HN | H53: 3SVJZG3 | I53: - | J53: - | K53: - | L53: - | M53: Windows 10 | N53: Yes | O53: 22H2 (19045.5965) | P53: MS 365 | Q53: Yes | R53: Yes | S53: 1879 | T53: No | U53: No | V53: Yes | W53: yes | X53: No | Y53: Yes | Z53: Yes | AA53: Yes | AB53: Yes | AD53: 4 | AE53: ชัยวัฒน์ จารุกรุณา (วัฒน์)
A54: narinrat.tin@trrgroup.com | B54: Narinrat Tinchadarak | C54: No | D54: HQ-PS-N036 | E54: HQ-PS-M036 | F54: DELL | G54: E2425HS | H54: 8520N54 | I54: - | J54: - | K54: - | L54: - | M54: Windows 11 | N54: Yes | O54: 24H2 (26100.4484) | P54: MS 365 | Q54: Yes | R54: Yes | S54: 1826 | T54: No | U54: No | V54: Yes | W54: yes | X54: No | Y54: Yes | Z54: Yes | AA54: Yes | AB54: Yes | AD54: 5 | AE54: วัชระ คิดโสดา (แจ็ค)
A55: thitiporn@trrgroup.com | B55: Thitiporn Chanvipava | C55: No | D55: HQ-PS-P001 | E55: HQ-PS-M037 | F55: LG | G55: 50PC1DR | H55: 16843009 | I55: - | J55: - | K55: - | L55: - | M55: Windows 11 | N55: Yes | O55: 21H2 (22000.2538) | P55: MS 365 | Q55: Yes | R55: Yes | S55: 1807 | T55: No | U55: Yes | V55: Yes | W55: yes | X55: No | Y55: Yes | Z55: Yes | AA55: Yes | AB55: Yes | AD55: 4 | AE55: ชัยวัฒน์ จารุกรุณา (วัฒน์)
A56: wongsathon.sae@trrgroup.com | B56: Wongsathon Saengcharoen | C56: No | D56: HQ-PS-N023 | E56: HQ-PS-M038 | F56: DELL | G56: S2421HN | H56: BSVJZG3 | I56: - | J56: - | K56: - | L56: - | M56: Windows 10 | N56: Yes | O56: 22H2 (19045.5965) | P56: MS 365 | Q56: Yes | R56: Yes | S56: 1880 | T56: No | U56: No | V56: Yes | W56: yes | X56: No | Y56: Yes | Z56: Yes | AA56: Yes | AB56: Yes | AD56: 4 | AE56: ชัยวัฒน์ จารุกรุณา (วัฒน์)
A57: jaruwan.pha@trrgroup.com | B57: Jaruwan Phajan | C57: No | D57: HQ-PS-N010 | E57: HQ-PS-M040 | F57: DELL | G57: SE2422H | H57: JR3Y814 | I57: - | J57: - | K57: - | L57: - | M57: Windows 11 | N57: Yes | O57: 24H2 (26100.4652) | P57: 2019 | Q57: Yes | R57: Yes | S57: 1810 | T57: No | U57: No | V57: Yes | W57: yes | X57: No | Y57: Yes | Z57: Yes | AA57: Yes | AB57: Yes | AD57: 5 | AE57: วัชระ คิดโสดา (แจ็ค)
A58: anusara.jar@trrgroup.com | B58: Anusara Jaroensuk | C58: No | D58: HQ-PS-N003 | E58: HQ-PS-M041 | F58: LG | G58: GSM5AB8 | H58: GSM5AB8 | I58: - | J58: - | K58: - | L58: - | M58: Windows 10 | N58: No | O58: 22H2 (19045.5965) | P58: MS 365 | Q58: Yes | R58: Yes | S58: 1820 | T58: No | U58: No | V58: Yes | W58: yes | X58: No | Y58: Yes | Z58: Yes | AA58: Yes | AB58: Yes | AD58: 5 | AE58: วัชระ คิดโสดา (แจ็ค)
A59: kunchisa.suk@trrgroup.com | B59: Kunchisa Sukthep | C59: No | D59: HQ-PS-N004 | E59: HQ-PS-M042 | F59: DELL | G59: S2319H | H59: TXC058811G3B | I59: - | J59: - | K59: - | L59: - | M59: Windows 10 | N59: No | O59: 22H2 (19045.6093) | P59: 2016 | Q59: No | R59: Yes | S59: 1809 | T59: No | U59: No | V59: Yes | W59: yes | X59: No | Y59: Yes | Z59: Yes | AA59: Yes | AB59: Yes | AD59: 5 | AE59: วัชระ คิดโสดา (แจ็ค)
...

Sheet Dashboard
A1: PM Asset IT Schedule
A2: TRRT
B4: Project Start Date | C4: 45824 | I4: Display Week | J4: 8 | M4: ="Week "&(M6-($C$4-WEEKDAY($C$4,1)+2))/7+1 -> Week 8 | T4: ="Week "&(T6-($C$4-WEEKDAY($C$4,1)+2))/7+1 -> Week 9 | AA4: ="Week "&(AA6-($C$4-WEEKDAY($C$4,1)+2))/7+1 -> Week 10 | AH4: ="Week "&(AH6-($C$4-WEEKDAY($C$4,1)+2))/7+1 -> Week 11 | AO4: ="Week "&(AO6-($C$4-WEEKDAY($C$4,1)+2))/7+1 -> Week 12 | AV4: ="Week "&(AV6-($C$4-WEEKDAY($C$4,1)+2))/7+1 -> Week 13 | BC4: ="Week "&(BC6-($C$4-WEEKDAY($C$4,1)+2))/7+1 -> Week 14 | BJ4: ="Week "&(BJ6-($C$4-WEEKDAY($C$4,1)+2))/7+1 -> Week 15
B5: Device All : ใช้งาน | C5: =D8+D20+D22+D25+D36+D40+D43+D47+D63 -> #REF! | D5: Completed | E5: =COUNTIFS(#REF!,$D$5) -> #REF! | F5: Remaining | G5: =IF(C5=0,"",C5-E5) -> #REF! | M5: =M6 -> 45873 | T5: =T6 -> 45880 | AA5: =AA6 -> 45887 | AH5: =AH6 -> 45894 | AO5: =AO6 -> 45901 | AV5: =AV6 -> 45908 | BC5: =BC6 -> 45915 | BJ5: =BJ6 -> 45922
M6: =C4-WEEKDAY(C4,1)+2+7*(J4-1) -> 45873 | N6: =M6+1 -> 45874 | O6: =N6+1 -> 45875 | P6: =O6+1 -> 45876 | Q6: =P6+1 -> 45877 | R6: =Q6+1 -> 45878 | S6: =R6+1 -> 45879 | T6: =S6+1 -> 45880 | U6: =T6+1 -> 45881 | ... BP6: =BO6+1 -> 45928 | BR6: Completed
A7: WBS | B7: TASK | C7: LEAD | D7: Device | E7: Completed | F7: คงเหลือ | G7: START | H7: END | I7: DAYS | J7: % DONE | K7: WORK DAYS | M7: =CHOOSE(WEEKDAY(M6,1),"S","M","T","W","T","F","S") -> M | N7: =CHOOSE(WEEKDAY(N6,1),"S","M","T","W","T","F","S") -> T | O7: =CHOOSE(WEEKDAY(O6,1),"S","M","T","W","T","F","S") -> W | P7: =CHOOSE(WEEKDAY(P6,1),"S","M","T","W","T","F","S") -> T | Q7: =CHOOSE(WEEKDAY(Q6,1),"S","M","T","W","T","F","S") -> F | R7: =CHOOSE(WEEKDAY(R6,1),"S","M","T","W","T","F","S") -> S | S7: =CHOOSE(WEEKDAY(S6,1),"S","M","T","W","T","F","S") -> S | T7: =CHOOSE(WEEKDAY(T6,1),"S","M","T","W","T","F","S") -> M | ... BP7: =CHOOSE(WEEKDAY(BP6,1),"S","M","T","W","T","F","S") -> S | BR7: Progress
A8: =IF(ISERROR(VALUE(SUBSTITUTE(prevWBS,".",""))),"1",IF(ISERROR(FIND("`",SUBSTITUTE(prevWBS,".","`",1))),TEXT(VALUE(prevWBS)+1,"#"),TEXT(VALUE(LEFT(prevWBS,FIND("`",SUBSTITUTE(prevWBS,".","`",1))-1))+1,"#"))) -> 1 | B8: TRR Corp | D8: =SUM(D9:D19) -> #REF! | E8: =SUM(E9:E19) -> #REF! | F8: =SUM(F9:F19) -> #REF! | H8: =IF(ISBLANK(G8)," - ",IF(I8=0,G8,G8+I8-1)) -> - | I8: =SUM(I9:I19) -> 40 | K8: =IF(OR(H8=0,G8=0)," - ",NETWORKDAYS(G8,H8)) -> -
A9: =IF(ISERROR(VALUE(SUBSTITUTE(prevWBS,".",""))),"0.1",IF(ISERROR(FIND("`",SUBSTITUTE(prevWBS,".","`",1))),prevWBS&".1",LEFT(prevWBS,FIND("`",SUBSTITUTE(prevWBS,".","`",1)))&IF(ISERROR(FIND("`",SUBSTITUTE(prevWBS,".","`",2))),VALUE(RIGHT(prevWBS,LEN(prevWBS)-FIND("`",SUBSTITUTE(prevWBS,".","`",1))))+1,VALUE(MID(prevWBS,FIND("`",SUBSTITUTE(prevWBS,".","`",1))+1,(FIND("`",SUBSTITUTE(prevWBS,".","`",2))-FIND("`",SUBSTITUTE(prevWBS,".","`",1))-1)))+1))) -> 1.1 | B9: ACC | C9: IT Support | D9: =COUNTIFS(#REF!,$B9,#REF!,$B$8,#REF!,"ใช้งาน") -> #REF! | E9: =COUNTIFS(#REF!,$B9,#REF!,$B$8,#REF!,Dashboard!$E$7) -> #REF! | F9: =D9-E9 -> #REF! | H9: =IF(ISBLANK(G9)," - ",IF(I9=0,G9,G9+I9-1)) -> - | I9: 10 | J9: =E9*100%/D9 -> #REF! | K9: =IF(OR(H9=0,G9=0)," - ",NETWORKDAYS(G9,H9)) -> -
A10: =IF(ISERROR(VALUE(SUBSTITUTE(prevWBS,".",""))),"0.1",IF(ISERROR(FIND("`",SUBSTITUTE(prevWBS,".","`",1))),prevWBS&".1",LEFT(prevWBS,FIND("`",SUBSTITUTE(prevWBS,".","`",1)))&IF(ISERROR(FIND("`",SUBSTITUTE(prevWBS,".","`",2))),VALUE(RIGHT(prevWBS,LEN(prevWBS)-FIND("`",SUBSTITUTE(prevWBS,".","`",1))))+1,VALUE(MID(prevWBS,FIND("`",SUBSTITUTE(prevWBS,".","`",1))+1,(FIND("`",SUBSTITUTE(prevWBS,".","`",2))-FIND("`",SUBSTITUTE(prevWBS,".","`",1))-1)))+1))) -> 1.2 | B10: FIN | C10: IT Support | D10: =COUNTIFS(#REF!,$B10,#REF!,$B$8,#REF!,"ใช้งาน") -> #REF! | E10: =COUNTIFS(#REF!,$B10,#REF!,$B$8,#REF!,Dashboard!$E$7) -> #REF! | F10: =D10-E10 -> #REF! | H10: =IF(ISBLANK(G10)," - ",IF(I10=0,G10,G10+I10-1)) -> - | I10: 3 | J10: =E10*100%/D10 -> #REF! | K10: =IF(OR(H10=0,G10=0)," - ",NETWORKDAYS(G10,H10)) -> -
A11: =IF(ISERROR(VALUE(SUBSTITUTE(prevWBS,".",""))),"0.1",IF(ISERROR(FIND("`",SUBSTITUTE(prevWBS,".","`",1))),prevWBS&".1",LEFT(prevWBS,FIND("`",SUBSTITUTE(prevWBS,".","`",1)))&IF(ISERROR(FIND("`",SUBSTITUTE(prevWBS,".","`",2))),VALUE(RIGHT(prevWBS,LEN(prevWBS)-FIND("`",SUBSTITUTE(prevWBS,".","`",1))))+1,VALUE(MID(prevWBS,FIND("`",SUBSTITUTE(prevWBS,".","`",1))+1,(FIND("`",SUBSTITUTE(prevWBS,".","`",2))-FIND("`",SUBSTITUTE(prevWBS,".","`",1))-1)))+1))) -> 1.3 | B11: HR | C11: IT Support | D11: =COUNTIFS(#REF!,$B11,#REF!,$B$8,#REF!,"ใช้งาน") -> #REF! | E11: =COUNTIFS(#REF!,$B11,#REF!,$B$8,#REF!,Dashboard!$E$7) -> #REF! | F11: =D11-E11 -> #REF! | H11: =IF(ISBLANK(G11)," - ",IF(I11=0,G11,G11+I11-1)) -> - | I11: 3 | J11: =E11*100%/D11 -> #REF! | K11: =IF(OR(H11=0,G11=0)," - ",NETWORKDAYS(G11,H11)) -> -
A12: =IF(ISERROR(VALUE(SUBSTITUTE(prevWBS,".",""))),"0.1",IF(ISERROR(FIND("`",SUBSTITUTE(prevWBS,".","`",1))),prevWBS&".1",LEFT(prevWBS,FIND("`",SUBSTITUTE(prevWBS,".","`",1)))&IF(ISERROR(FIND("`",SUBSTITUTE(prevWBS,".","`",2))),VALUE(RIGHT(prevWBS,LEN(prevWBS)-FIND("`",SUBSTITUTE(prevWBS,".","`",1))))+1,VALUE(MID(prevWBS,FIND("`",SUBSTITUTE(prevWBS,".","`",1))+1,(FIND("`",SUBSTITUTE(prevWBS,".","`",2))-FIND("`",SUBSTITUTE(prevWBS,".","`",1))-1)))+1))) -> 1.4 | B12: SAL | C12: IT Support | D12: =COUNTIFS(#REF!,$B12,#REF!,$B$8,#REF!,"ใช้งาน") -> #REF! | E12: =COUNTIFS(#REF!,$B12,#REF!,$B$8,#REF!,Dashboard!$E$7) -> #REF! | F12: =D12-E12 -> #REF! | H12: =IF(ISBLANK(G12)," - ",IF(I12=0,G12,G12+I12-1)) -> - | I12: 3 | J12: =E12*100%/D12 -> #REF! | K12: =IF(OR(H12=0,G12=0)," - ",NETWORKDAYS(G12,H12)) -> -
A13: =IF(ISERROR(VALUE(SUBSTITUTE(prevWBS,".",""))),"0.1",IF(ISERROR(FIND("`",SUBSTITUTE(prevWBS,".","`",1))),prevWBS&".1",LEFT(prevWBS,FIND("`",SUBSTITUTE(prevWBS,".","`",1)))&IF(ISERROR(FIND("`",SUBSTITUTE(prevWBS,".","`",2))),VALUE(RIGHT(prevWBS,LEN(prevWBS)-FIND("`",SUBSTITUTE(prevWBS,".","`",1))))+1,VALUE(MID(prevWBS,FIND("`",SUBSTITUTE(prevWBS,".","`",1))+1,(FIND("`",SUBSTITUTE(prevWBS,".","`",2))-FIND("`",SUBSTITUTE(prevWBS,".","`",1))-1)))+1))) -> 1.5 | B13: PLN | C13: IT Support | D13: =COUNTIFS(#REF!,$B13,#REF!,$B$8,#REF!,"ใช้งาน") -> #REF! | E13: =COUNTIFS(#REF!,$B13,#REF!,$B$8,#REF!,Dashboard!$E$7) -> #REF! | F13: =D13-E13 -> #REF! | H13: =IF(ISBLANK(G13)," - ",IF(I13=0,G13,G13+I13-1)) -> - | I13: 5 | J13: =E13*100%/D13 -> #REF! | K13: =IF(OR(H13=0,G13=0)," - ",NETWORKDAYS(G13,H13)) -> -
A14: =IF(ISERROR(VALUE(SUBSTITUTE(prevWBS,".",""))),"0.1",IF(ISERROR(FIND("`",SUBSTITUTE(prevWBS,".","`",1))),prevWBS&".1",LEFT(prevWBS,FIND("`",SUBSTITUTE(prevWBS,".","`",1)))&IF(ISERROR(FIND("`",SUBSTITUTE(prevWBS,".","`",2))),VALUE(RIGHT(prevWBS,LEN(prevWBS)-FIND("`",SUBSTITUTE(prevWBS,".","`",1))))+1,VALUE(MID(prevWBS,FIND("`",SUBSTITUTE(prevWBS,".","`",1))+1,(FIND("`",SUBSTITUTE(prevWBS,".","`",2))-FIND("`",SUBSTITUTE(prevWBS,".","`",1))-1)))+1))) -> 1.6 | B14: IT | C14: IT Support | D14: =COUNTIFS(#REF!,$B14,#REF!,$B$8,#REF!,"ใช้งาน") -> #REF! | E14: =COUNTIFS(#REF!,$B14,#REF!,$B$8,#REF!,Dashboard!$E$7) -> #REF! | F14: =D14-E14 -> #REF! | H14: =IF(ISBLANK(G14)," - ",IF(I14=0,G14,G14+I14-1)) -> - | I14: 2 | J14: =E14*100%/D14 -> #REF! | K14: =IF(OR(H14=0,G14=0)," - ",NETWORKDAYS(G14,H14)) -> -
A15: =IF(ISERROR(VALUE(SUBSTITUTE(prevWBS,".",""))),"0.1",IF(ISERROR(FIND("`",SUBSTITUTE(prevWBS,".","`",1))),prevWBS&".1",LEFT(prevWBS,FIND("`",SUBSTITUTE(prevWBS,".","`",1)))&IF(ISERROR(FIND("`",SUBSTITUTE(prevWBS,".","`",2))),VALUE(RIGHT(prevWBS,LEN(prevWBS)-FIND("`",SUBSTITUTE(prevWBS,".","`",1))))+1,VALUE(MID(prevWBS,FIND("`",SUBSTITUTE(prevWBS,".","`",1))+1,(FIND("`",SUBSTITUTE(prevWBS,".","`",2))-FIND("`",SUBSTITUTE(prevWBS,".","`",1))-1)))+1))) -> 1.7 | B15: SEC | C15: IT Support | D15: =COUNTIFS(#REF!,$B15,#REF!,$B$8,#REF!,"ใช้งาน") -> #REF! | E15: =COUNTIFS(#REF!,$B15,#REF!,$B$8,#REF!,Dashboard!$E$7) -> #REF! | F15: =D15-E15 -> #REF! | H15: =IF(ISBLANK(G15)," - ",IF(I15=0,G15,G15+I15-1)) -> - | I15: 1 | J15: =E15*100%/D15 -> #REF! | K15: =IF(OR(H15=0,G15=0)," - ",NETWORKDAYS(G15,H15)) -> -
A16: =IF(ISERROR(VALUE(SUBSTITUTE(prevWBS,".",""))),"0.1",IF(ISERROR(FIND("`",SUBSTITUTE(prevWBS,".","`",1))),prevWBS&".1",LEFT(prevWBS,FIND("`",SUBSTITUTE(prevWBS,".","`",1)))&IF(ISERROR(FIND("`",SUBSTITUTE(prevWBS,".","`",2))),VALUE(RIGHT(prevWBS,LEN(prevWBS)-FIND("`",SUBSTITUTE(prevWBS,".","`",1))))+1,VALUE(MID(prevWBS,FIND("`",SUBSTITUTE(prevWBS,".","`",1))+1,(FIND("`",SUBSTITUTE(prevWBS,".","`",2))-FIND("`",SUBSTITUTE(prevWBS,".","`",1))-1)))+1))) -> 1.8 | B16: LAW | C16: IT Support | D16: =COUNTIFS(#REF!,$B16,#REF!,$B$8,#REF!,"ใช้งาน") -> #REF! | E16: =COUNTIFS(#REF!,$B16,#REF!,$B$8,#REF!,Dashboard!$E$7) -> #REF! | F16: =D16-E16 -> #REF! | H16: =IF(ISBLANK(G16)," - ",IF(I16=0,G16,G16+I16-1)) -> - | I16: 2 | J16: =E16*100%/D16 -> #REF! | K16: =IF(OR(H16=0,G16=0)," - ",NETWORKDAYS(G16,H16)) -> -
A17: =IF(ISERROR(VALUE(SUBSTITUTE(prevWBS,".",""))),"0.1",IF(ISERROR(FIND("`",SUBSTITUTE(prevWBS,".","`",1))),prevWBS&".1",LEFT(prevWBS,FIND("`",SUBSTITUTE(prevWBS,".","`",1)))&IF(ISERROR(FIND("`",SUBSTITUTE(prevWBS,".","`",2))),VALUE(RIGHT(prevWBS,LEN(prevWBS)-FIND("`",SUBSTITUTE(prevWBS,".","`",1))))+1,VALUE(MID(prevWBS,FIND("`",SUBSTITUTE(prevWBS,".","`",1))+1,(FIND("`",SUBSTITUTE(prevWBS,".","`",2))-FIND("`",SUBSTITUTE(prevWBS,".","`",1))-1)))+1))) -> 1.9 | B17: Project | C17: IT Support | D17: =COUNTIFS(#REF!,$B17,#REF!,$B$8,#REF!,"ใช้งาน") -> #REF! | E17: =COUNTIFS(#REF!,$B17,#REF!,$B$8,#REF!,Dashboard!$E$7) -> #REF! | F17: =D17-E17 -> #REF! | H17: =IF(ISBLANK(G17)," - ",IF(I17=0,G17,G17+I17-1)) -> - | I17: 4 | J17: =E17*100%/D17 -> #REF! | K17: =IF(OR(H17=0,G17=0)," - ",NETWORKDAYS(G17,H17)) -> -
A18: =IF(ISERROR(VALUE(SUBSTITUTE(prevWBS,".",""))),"0.1",IF(ISERROR(FIND("`",SUBSTITUTE(prevWBS,".","`",1))),prevWBS&".1",LEFT(prevWBS,FIND("`",SUBSTITUTE(prevWBS,".","`",1)))&IF(ISERROR(FIND("`",SUBSTITUTE(prevWBS,".","`",2))),VALUE(RIGHT(prevWBS,LEN(prevWBS)-FIND("`",SUBSTITUTE(prevWBS,".","`",1))))+1,VALUE(MID(prevWBS,FIND("`",SUBSTITUTE(prevWBS,".","`",1))+1,(FIND("`",SUBSTITUTE(prevWBS,".","`",2))-FIND("`",SUBSTITUTE(prevWBS,".","`",1))-1)))+1))) -> 1.10 | B18: MD | C18: IT Support | D18: =COUNTIFS(#REF!,$B18,#REF!,$B$8,#REF!,"ใช้งาน") -> #REF! | E18: =COUNTIFS(#REF!,$B18,#REF!,$B$8,#REF!,Dashboard!$E$7) -> #REF! | F18: =D18-E18 -> #REF! | H18: =IF(ISBLANK(G18)," - ",IF(I18=0,G18,G18+I18-1)) -> - | I18: 2 | J18: =E18*100%/D18 -> #REF! | K18: =IF(OR(H18=0,G18=0)," - ",NETWORKDAYS(G18,H18)) -> -
A19: =IF(ISERROR(VALUE(SUBSTITUTE(prevWBS,".",""))),"0.1",IF(ISERROR(FIND("`",SUBSTITUTE(prevWBS,".","`",1))),prevWBS&".1",LEFT(prevWBS,FIND("`",SUBSTITUTE(prevWBS,".","`",1)))&IF(ISERROR(FIND("`",SUBSTITUTE(prevWBS,".","`",2))),VALUE(RIGHT(prevWBS,LEN(prevWBS)-FIND("`",SUBSTITUTE(prevWBS,".","`",1))))+1,VALUE(MID(prevWBS,FIND("`",SUBSTITUTE(prevWBS,".","`",1))+1,(FIND("`",SUBSTITUTE(prevWBS,".","`",2))-FIND("`",SUBSTITUTE(prevWBS,".","`",1))-1)))+1))) -> 1.11 | B19: PUR | C19: IT Support | D19: =COUNTIFS(#REF!,$B19,#REF!,$B$8,#REF!,"ใช้งาน") -> #REF! | E19: =COUNTIFS(#REF!,$B19,#REF!,$B$8,#REF!,Dashboard!$E$7) -> #REF! | F19: =D19-E19 -> #REF! | G19: 45889 | H19: =IF(ISBLANK(G19)," - ",IF(I19=0,G19,G19+I19-1)) -> 45893 | I19: 5 | J19: =E19*100%/D19 -> #REF! | K19: =IF(OR(H19=0,G19=0)," - ",NETWORKDAYS(G19,H19)) -> 3
A20: =IF(ISERROR(VALUE(SUBSTITUTE(prevWBS,".",""))),"1",IF(ISERROR(FIND("`",SUBSTITUTE(prevWBS,".","`",1))),TEXT(VALUE(prevWBS)+1,"#"),TEXT(VALUE(LEFT(prevWBS,FIND("`",SUBSTITUTE(prevWBS,".","`",1))-1))+1,"#"))) -> 2 | B20: TRRT | D20: =SUM(D21) -> #REF! | E20: =SUM(E21) -> #REF! | F20: =SUM(F21) -> #REF! | H20: =IF(ISBLANK(G20)," - ",IF(I20=0,G20,G20+I20-1)) -> - | I20: =SUM(I21:I21) -> 10 | K20: =IF(OR(H20=0,G20=0)," - ",NETWORKDAYS(G20,H20)) -> -
A21: =IF(ISERROR(VALUE(SUBSTITUTE(prevWBS,".",""))),"0.1",IF(ISERROR(FIND("`",SUBSTITUTE(prevWBS,".","`",1))),prevWBS&".1",LEFT(prevWBS,FIND("`",SUBSTITUTE(prevWBS,".","`",1)))&IF(ISERROR(FIND("`",SUBSTITUTE(prevWBS,".","`",2))),VALUE(RIGHT(prevWBS,LEN(prevWBS)-FIND("`",SUBSTITUTE(prevWBS,".","`",1))))+1,VALUE(MID(prevWBS,FIND("`",SUBSTITUTE(prevWBS,".","`",1))+1,(FIND("`",SUBSTITUTE(prevWBS,".","`",2))-FIND("`",SUBSTITUTE(prevWBS,".","`",1))-1)))+1))) -> 2.1 | B21: IT | C21: IT Support | D21: =COUNTIFS(#REF!,$B21,#REF!,$B$20,#REF!,"ใช้งาน") -> #REF! | E21: =COUNTIFS(#REF!,$B21,#REF!,$B$20,#REF!,Dashboard!$E$7) -> #REF! | F21: =D21-E21 -> #REF! | G21: 45875 | H21: =IF(ISBLANK(G21)," - ",IF(I21=0,G21,G21+I21-1)) -> 45884 | I21: 10 | J21: =E21*100%/D21 -> #REF! | K21: =IF(OR(H21=0,G21=0)," - ",NETWORKDAYS(G21,H21)) -> 8
A22: =IF(ISERROR(VALUE(SUBSTITUTE(prevWBS,".",""))),"1",IF(ISERROR(FIND("`",SUBSTITUTE(prevWBS,".","`",1))),TEXT(VALUE(prevWBS)+1,"#"),TEXT(VALUE(LEFT(prevWBS,FIND("`",SUBSTITUTE(prevWBS,".","`",1))-1))+1,"#"))) -> 3 | B22: TRRL | D22: =SUM(D23:D24) -> #REF! | E22: =SUM(E23:E24) -> #REF! | F22: =SUM(F23:F24) -> #REF! | H22: =IF(ISBLANK(G22)," - ",IF(I22=0,G22,G22+I22-1)) -> - | K22: =IF(OR(H22=0,G22=0)," - ",NETWORKDAYS(G22,H22)) -> -
A23: =IF(ISERROR(VALUE(SUBSTITUTE(prevWBS,".",""))),"0.1",IF(ISERROR(FIND("`",SUBSTITUTE(prevWBS,".","`",1))),prevWBS&".1",LEFT(prevWBS,FIND("`",SUBSTITUTE(prevWBS,".","`",1)))&IF(ISERROR(FIND("`",SUBSTITUTE(prevWBS,".","`",2))),VALUE(RIGHT(prevWBS,LEN(prevWBS)-FIND("`",SUBSTITUTE(prevWBS,".","`",1))))+1,VALUE(MID(prevWBS,FIND("`",SUBSTITUTE(prevWBS,".","`",1))+1,(FIND("`",SUBSTITUTE(prevWBS,".","`",2))-FIND("`",SUBSTITUTE(prevWBS,".","`",1))-1)))+1))) -> 3.1 | B23: Credit | C23: IT Support | D23: =COUNTIFS(#REF!,$B23,#REF!,$B$22,#REF!,"ใช้งาน") -> #REF! | E23: =COUNTIFS(#REF!,$B23,#REF!,$B$22,#REF!,Dashboard!$E$7) -> #REF! | F23: =D23-E23 -> #REF! | G23: 45887 | H23: =IF(ISBLANK(G23)," - ",IF(I23=0,G23,G23+I23-1)) -> 45887 | I23: 1 | J23: =E23*100%/D23 -> #REF! | K23: =IF(OR(H23=0,G23=0)," - ",NETWORKDAYS(G23,H23)) -> 1
A24: =IF(ISERROR(VALUE(SUBSTITUTE(prevWBS,".",""))),"0.1",IF(ISERROR(FIND("`",SUBSTITUTE(prevWBS,".","`",1))),prevWBS&".1",LEFT(prevWBS,FIND("`",SUBSTITUTE(prevWBS,".","`",1)))&IF(ISERROR(FIND("`",SUBSTITUTE(prevWBS,".","`",2))),VALUE(RIGHT(prevWBS,LEN(prevWBS)-FIND("`",SUBSTITUTE(prevWBS,".","`",1))))+1,VALUE(MID(prevWBS,FIND("`",SUBSTITUTE(prevWBS,".","`",1))+1,(FIND("`",SUBSTITUTE(prevWBS,".","`",2))-FIND("`",SUBSTITUTE(prevWBS,".","`",1))-1)))+1))) -> 3.2 | B24: FNS | C24: IT Support | D24: =COUNTIFS(#REF!,$B24,#REF!,$B$22,#REF!,"ใช้งาน") -> #REF! | E24: =COUNTIFS(#REF!,$B24,#REF!,$B$22,#REF!,Dashboard!$E$7) -> #REF! | F24: =D24-E24 -> #REF! | G24: 45888 | H24: =IF(ISBLANK(G24)," - ",IF(I24=0,G24,G24+I24-1)) -> 45888 | I24: 1 | J24: =E24*100%/D24 -> #REF! | K24: =IF(OR(H24=0,G24=0)," - ",NETWORKDAYS(G24,H24)) -> 1
A25: =IF(ISERROR(VALUE(SUBSTITUTE(prevWBS,".",""))),"1",IF(ISERROR(FIND("`",SUBSTITUTE(prevWBS,".","`",1))),TEXT(VALUE(prevWBS)+1,"#"),TEXT(VALUE(LEFT(prevWBS,FIND("`",SUBSTITUTE(prevWBS,".","`",1))-1))+1,"#"))) -> 4 | B25: PS | D25: =SUM(D26:D35) -> #REF! | E25: =SUM(E26:E35) -> #REF! | F25: =SUM(F26:F35) -> #REF! | H25: =IF(ISBLANK(G25)," - ",IF(I25=0,G25,G25+I25-1)) -> - | I25: =SUM(I26:I35) -> 29 | K25: =IF(OR(H25=0,G25=0)," - ",NETWORKDAYS(G25,H25)) -> -
A26: =IF(ISERROR(VALUE(SUBSTITUTE(prevWBS,".",""))),"0.1",IF(ISERROR(FIND("`",SUBSTITUTE(prevWBS,".","`",1))),prevWBS&".1",LEFT(prevWBS,FIND("`",SUBSTITUTE(prevWBS,".","`",1)))&IF(ISERROR(FIND("`",SUBSTITUTE(prevWBS,".","`",2))),VALUE(RIGHT(prevWBS,LEN(prevWBS)-FIND("`",SUBSTITUTE(prevWBS,".","`",1))))+1,VALUE(MID(prevWBS,FIND("`",SUBSTITUTE(prevWBS,".","`",1))+1,(FIND("`",SUBSTITUTE(prevWBS,".","`",2))-FIND("`",SUBSTITUTE(prevWBS,".","`",1))-1)))+1))) -> 4.1 | B26: ACC | C26: IT Support | D26: =COUNTIFS(#REF!,$B26,#REF!,$B$25,#REF!,"ใช้งาน") -> #REF! | E26: =COUNTIFS(#REF!,$B26,#REF!,$B$25,#REF!,Dashboard!$E$7) -> #REF! | F26: =D26-E26 -> #REF! | G26: 45819 | H26: =IF(ISBLANK(G26)," - ",IF(I26=0,G26,G26+I26-1)) -> 45833 | I26: 15 | J26: =E26*100%/D26 -> #REF! | K26: =IF(OR(H26=0,G26=0)," - ",NETWORKDAYS(G26,H26)) -> 11
A27: =IF(ISERROR(VALUE(SUBSTITUTE(prevWBS,".",""))),"0.1",IF(ISERROR(FIND("`",SUBSTITUTE(prevWBS,".","`",1))),prevWBS&".1",LEFT(prevWBS,FIND("`",SUBSTITUTE(prevWBS,".","`",1)))&IF(ISERROR(FIND("`",SUBSTITUTE(prevWBS,".","`",2))),VALUE(RIGHT(prevWBS,LEN(prevWBS)-FIND("`",SUBSTITUTE(prevWBS,".","`",1))))+1,VALUE(MID(prevWBS,FIND("`",SUBSTITUTE(prevWBS,".","`",1))+1,(FIND("`",SUBSTITUTE(prevWBS,".","`",2))-FIND("`",SUBSTITUTE(prevWBS,".","`",1))-1)))+1))) -> 4.2 | B27: Audit | C27: IT Support | D27: =COUNTIFS(#REF!,$B27,#REF!,$B$25,#REF!,"ใช้งาน") -> #REF! | E27: =COUNTIFS(#REF!,$B27,#REF!,$B$25,#REF!,Dashboard!$E$7) -> #REF! | F27: =D27-E27 -> #REF! | G27: 45834 | H27: =IF(ISBLANK(G27)," - ",IF(I27=0,G27,G27+I27-1)) -> 45835 | I27: 2 | J27: =E27*100%/D27 -> #REF! | K27: =IF(OR(H27=0,G27=0)," - ",NETWORKDAYS(G27,H27)) -> 2
A28: =IF(ISERROR(VALUE(SUBSTITUTE(prevWBS,".",""))),"0.1",IF(ISERROR(FIND("`",SUBSTITUTE(prevWBS,".","`",1))),prevWBS&".1",LEFT(prevWBS,FIND("`",SUBSTITUTE(prevWBS,".","`",1)))&IF(ISERROR(FIND("`",SUBSTITUTE(prevWBS,".","`",2))),VALUE(RIGHT(prevWBS,LEN(prevWBS)-FIND("`",SUBSTITUTE(prevWBS,".","`",1))))+1,VALUE(MID(prevWBS,FIND("`",SUBSTITUTE(prevWBS,".","`",1))+1,(FIND("`",SUBSTITUTE(prevWBS,".","`",2))-FIND("`",SUBSTITUTE(prevWBS,".","`",1))-1)))+1))) -> 4.3 | B28: BUG | C28: IT Support | D28: =COUNTIFS(#REF!,$B28,#REF!,$B$25,#REF!,"ใช้งาน") -> #REF! | E28: =COUNTIFS(#REF!,$B28,#REF!,$B$25,#REF!,Dashboard!$E$7) -> #REF! | F28: =D28-E28 -> #REF! | G28: 45838 | H28: =IF(ISBLANK(G28)," - ",IF(I28=0,G28,G28+I28-1)) -> 45838 | I28: 1 | J28: =E28*100%/D28 -> #REF! | K28: =IF(OR(H28=0,G28=0)," - ",NETWORKDAYS(G28,H28)) -> 1
A29: =IF(ISERROR(VALUE(SUBSTITUTE(prevWBS,".",""))),"0.1",IF(ISERROR(FIND("`",SUBSTITUTE(prevWBS,".","`",1))),prevWBS&".1",LEFT(prevWBS,FIND("`",SUBSTITUTE(prevWBS,".","`",1)))&IF(ISERROR(FIND("`",SUBSTITUTE(prevWBS,".","`",2))),VALUE(RIGHT(prevWBS,LEN(prevWBS)-FIND("`",SUBSTITUTE(prevWBS,".","`",1))))+1,VALUE(MID(prevWBS,FIND("`",SUBSTITUTE(prevWBS,".","`",1))+1,(FIND("`",SUBSTITUTE(prevWBS,".","`",2))-FIND("`",SUBSTITUTE(prevWBS,".","`",1))-1)))+1))) -> 4.4 | B29: CAS | C29: IT Support | D29: =COUNTIFS(#REF!,$B29,#REF!,$B$25,#REF!,"ใช้งาน") -> #REF! | E29: =COUNTIFS(#REF!,$B29,#REF!,$B$25,#REF!,Dashboard!$E$7) -> #REF! | F29: =D29-E29 -> #REF! | G29: 45838 | H29: =IF(ISBLANK(G29)," - ",IF(I29=0,G29,G29+I29-1)) -> 45838 | I29: 1 | J29: =E29*100%/D29 -> #REF! | K29: =IF(OR(H29=0,G29=0)," - ",NETWORKDAYS(G29,H29)) -> 1
A30: =IF(ISERROR(VALUE(SUBSTITUTE(prevWBS,".",""))),"0.1",IF(ISERROR(FIND("`",SUBSTITUTE(prevWBS,".","`",1))),prevWBS&".1",LEFT(prevWBS,FIND("`",SUBSTITUTE(prevWBS,".","`",1)))&IF(ISERROR(FIND("`",SUBSTITUTE(prevWBS,".","`",2))),VALUE(RIGHT(prevWBS,LEN(prevWBS)-FIND("`",SUBSTITUTE(prevWBS,".","`",1))))+1,VALUE(MID(prevWBS,FIND("`",SUBSTITUTE(prevWBS,".","`",1))+1,(FIND("`",SUBSTITUTE(prevWBS,".","`",2))-FIND("`",SUBSTITUTE(prevWBS,".","`",1))-1)))+1))) -> 4.5 | B30: ERP | C30: IT Support | D30: =COUNTIFS(#REF!,$B30,#REF!,$B$25,#REF!,"ใช้งาน") -> #REF! | E30: =COUNTIFS(#REF!,$B30,#REF!,$B$25,#REF!,Dashboard!$E$7) -> #REF! | F30: =D30-E30 -> #REF! | G30: 45839 | H30: =IF(ISBLANK(G30)," - ",IF(I30=0,G30,G30+I30-1)) -> 45840 | I30: 2 | J30: =E30*100%/D30 -> #REF! | K30: =IF(OR(H30=0,G30=0)," - ",NETWORKDAYS(G30,H30)) -> 2
A31: =IF(ISERROR(VALUE(SUBSTITUTE(prevWBS,".",""))),"0.1",IF(ISERROR(FIND("`",SUBSTITUTE(prevWBS,".","`",1))),prevWBS&".1",LEFT(prevWBS,FIND("`",SUBSTITUTE(prevWBS,".","`",1)))&IF(ISERROR(FIND("`",SUBSTITUTE(prevWBS,".","`",2))),VALUE(RIGHT(prevWBS,LEN(prevWBS)-FIND("`",SUBSTITUTE(prevWBS,".","`",1))))+1,VALUE(MID(prevWBS,FIND("`",SUBSTITUTE(prevWBS,".","`",1))+1,(FIND("`",SUBSTITUTE(prevWBS,".","`",2))-FIND("`",SUBSTITUTE(prevWBS,".","`",1))-1)))+1))) -> 4.6 | B31: FIN | C31: IT Support | D31: =COUNTIFS(#REF!,$B31,#REF!,$B$25,#REF!,"ใช้งาน") -> #REF! | E31: =COUNTIFS(#REF!,$B31,#REF!,$B$25,#REF!,Dashboard!$E$7) -> #REF! | F31: =D31-E31 -> #REF! | G31: 45841 | H31: =IF(ISBLANK(G31)," - ",IF(I31=0,G31,G31+I31-1)) -> 45842 | I31: 2 | J31: =E31*100%/D31 -> #REF! | K31: =IF(OR(H31=0,G31=0)," - ",NETWORKDAYS(G31,H31)) -> 2
A32: =IF(ISERROR(VALUE(SUBSTITUTE(prevWBS,".",""))),"0.1",IF(ISERROR(FIND("`",SUBSTITUTE(prevWBS,".","`",1))),prevWBS&".1",LEFT(prevWBS,FIND("`",SUBSTITUTE(prevWBS,".","`",1)))&IF(ISERROR(FIND("`",SUBSTITUTE(prevWBS,".","`",2))),VALUE(RIGHT(prevWBS,LEN(prevWBS)-FIND("`",SUBSTITUTE(prevWBS,".","`",1))))+1,VALUE(MID(prevWBS,FIND("`",SUBSTITUTE(prevWBS,".","`",1))+1,(FIND("`",SUBSTITUTE(prevWBS,".","`",2))-FIND("`",SUBSTITUTE(prevWBS,".","`",1))-1)))+1))) -> 4.7 | B32: MD | C32: IT Support | D32: =COUNTIFS(#REF!,$B32,#REF!,$B$25,#REF!,"ใช้งาน") -> #REF! | E32: =COUNTIFS(#REF!,$B32,#REF!,$B$25,#REF!,Dashboard!$E$7) -> #REF! | F32: =D32-E32 -> #REF! | G32: 45845 | H32: =IF(ISBLANK(G32)," - ",IF(I32=0,G32,G32+I32-1)) -> 45846 | I32: 2 | J32: =E32*100%/D32 -> #REF! | K32: =IF(OR(H32=0,G32=0)," - ",NETWORKDAYS(G32,H32)) -> 2
A33: =IF(ISERROR(VALUE(SUBSTITUTE(prevWBS,".",""))),"0.1",IF(ISERROR(FIND("`",SUBSTITUTE(prevWBS,".","`",1))),prevWBS&".1",LEFT(prevWBS,FIND("`",SUBSTITUTE(prevWBS,".","`",1)))&IF(ISERROR(FIND("`",SUBSTITUTE(prevWBS,".","`",2))),VALUE(RIGHT(prevWBS,LEN(prevWBS)-FIND("`",SUBSTITUTE(prevWBS,".","`",1))))+1,VALUE(MID(prevWBS,FIND("`",SUBSTITUTE(prevWBS,".","`",1))+1,(FIND("`",SUBSTITUTE(prevWBS,".","`",2))-FIND("`",SUBSTITUTE(prevWBS,".","`",1))-1)))+1))) -> 4.8 | B33: PUR | C33: IT Support | D33: =COUNTIFS(#REF!,$B33,#REF!,$B$25,#REF!,"ใช้งาน") -> #REF! | E33: =COUNTIFS(#REF!,$B33,#REF!,$B$25,#REF!,Dashboard!$E$7) -> #REF! | F33: =D33-E33 -> #REF! | G33: 45847 | H33: =IF(ISBLANK(G33)," - ",IF(I33=0,G33,G33+I33-1)) -> 45848 | I33: 2 | J33: =E33*100%/D33 -> #REF! | K33: =IF(OR(H33=0,G33=0)," - ",NETWORKDAYS(G33,H33)) -> 2
A34: =IF(ISERROR(VALUE(SUBSTITUTE(prevWBS,".",""))),"0.1",IF(ISERROR(FIND("`",SUBSTITUTE(prevWBS,".","`",1))),prevWBS&".1",LEFT(prevWBS,FIND("`",SUBSTITUTE(prevWBS,".","`",1)))&IF(ISERROR(FIND("`",SUBSTITUTE(prevWBS,".","`",2))),VALUE(RIGHT(prevWBS,LEN(prevWBS)-FIND("`",SUBSTITUTE(prevWBS,".","`",1))))+1,VALUE(MID(prevWBS,FIND("`",SUBSTITUTE(prevWBS,".","`",1))+1,(FIND("`",SUBSTITUTE(prevWBS,".","`",2))-FIND("`",SUBSTITUTE(prevWBS,".","`",1))-1)))+1))) -> 4.9 | B34: SAL | C34: IT Support | D34: =COUNTIFS(#REF!,$B34,#REF!,$B$25,#REF!,"ใช้งาน") -> #REF! | E34: =COUNTIFS(#REF!,$B34,#REF!,$B$25,#REF!,Dashboard!$E$7) -> #REF! | F34: =D34-E34 -> #REF! | G34: 45849 | H34: =IF(ISBLANK(G34)," - ",IF(I34=0,G34,G34+I34-1)) -> 45849 | I34: 1 | J34: =E34*100%/D34 -> #REF! | K34: =IF(OR(H34=0,G34=0)," - ",NETWORKDAYS(G34,H34)) -> 1
A35: =IF(ISERROR(VALUE(SUBSTITUTE(prevWBS,".",""))),"0.1",IF(ISERROR(FIND("`",SUBSTITUTE(prevWBS,".","`",1))),prevWBS&".1",LEFT(prevWBS,FIND("`",SUBSTITUTE(prevWBS,".","`",1)))&IF(ISERROR(FIND("`",SUBSTITUTE(prevWBS,".","`",2))),VALUE(RIGHT(prevWBS,LEN(prevWBS)-FIND("`",SUBSTITUTE(prevWBS,".","`",1))))+1,VALUE(MID(prevWBS,FIND("`",SUBSTITUTE(prevWBS,".","`",1))+1,(FIND("`",SUBSTITUTE(prevWBS,".","`",2))-FIND("`",SUBSTITUTE(prevWBS,".","`",1))-1)))+1))) -> 4.10 | B35: SEC | C35: IT Support | D35: =COUNTIFS(#REF!,$B35,#REF!,$B$25,#REF!,"ใช้งาน") -> #REF! | E35: =COUNTIFS(#REF!,$B35,#REF!,$B$25,#REF!,Dashboard!$E$7) -> #REF! | F35: =D35-E35 -> #REF! | G35: 45849 | H35: =IF(ISBLANK(G35)," - ",IF(I35=0,G35,G35+I35-1)) -> 45849 | I35: 1 | J35: =E35*100%/D35 -> #REF! | K35: =IF(OR(H35=0,G35=0)," - ",NETWORKDAYS(G35,H35)) -> 1
A36: =IF(ISERROR(VALUE(SUBSTITUTE(prevWBS,".",""))),"1",IF(ISERROR(FIND("`",SUBSTITUTE(prevWBS,".","`",1))),TEXT(VALUE(prevWBS)+1,"#"),TEXT(VALUE(LEFT(prevWBS,FIND("`",SUBSTITUTE(prevWBS,".","`",1))-1))+1,"#"))) -> 5 | B36: SSEC | D36: =SUM(D37:D39) -> #REF! | E36: =SUM(E37:E39) -> 0 | F36: =SUM(F37:F39) -> 0 | H36: =IF(ISBLANK(G36)," - ",IF(I36=0,G36,G36+I36-1)) -> - | I36: =SUM(I37:I39) -> 7 | K36: =IF(OR(H36=0,G36=0)," - ",NETWORKDAYS(G36,H36)) -> -
A37: =IF(ISERROR(VALUE(SUBSTITUTE(prevWBS,".",""))),"0.1",IF(ISERROR(FIND("`",SUBSTITUTE(prevWBS,".","`",1))),prevWBS&".1",LEFT(prevWBS,FIND("`",SUBSTITUTE(prevWBS,".","`",1)))&IF(ISERROR(FIND("`",SUBSTITUTE(prevWBS,".","`",2))),VALUE(RIGHT(prevWBS,LEN(prevWBS)-FIND("`",SUBSTITUTE(prevWBS,".","`",1))))+1,VALUE(MID(prevWBS,FIND("`",SUBSTITUTE(prevWBS,".","`",1))+1,(FIND("`",SUBSTITUTE(prevWBS,".","`",2))-FIND("`",SUBSTITUTE(prevWBS,".","`",1))-1)))+1))) -> 5.1 | B37: OFF | C37: IT Support | D37: =COUNTIFS(#REF!,$B37,#REF!,$B$36,#REF!,"ใช้งาน") -> #REF! | E37: =COUNTIFS(#REF!,$B37,#REF!,$B$36,#REF!,Dashboard!$E$7)+F37 -> 0 | F37: =D37-E37 -> 0 | H37: =IF(ISBLANK(G37)," - ",IF(I37=0,G37,G37+I37-1)) -> - | I37: 5 | J37: =E37*100%/D37 -> 0 | K37: =IF(OR(H37=0,G37=0)," - ",NETWORKDAYS(G37,H37)) -> -
A38: =IF(ISERROR(VALUE(SUBSTITUTE(prevWBS,".",""))),"0.1",IF(ISERROR(FIND("`",SUBSTITUTE(prevWBS,".","`",1))),prevWBS&".1",LEFT(prevWBS,FIND("`",SUBSTITUTE(prevWBS,".","`",1)))&IF(ISERROR(FIND("`",SUBSTITUTE(prevWBS,".","`",2))),VALUE(RIGHT(prevWBS,LEN(prevWBS)-FIND("`",SUBSTITUTE(prevWBS,".","`",1))))+1,VALUE(MID(prevWBS,FIND("`",SUBSTITUTE(prevWBS,".","`",1))+1,(FIND("`",SUBSTITUTE(prevWBS,".","`",2))-FIND("`",SUBSTITUTE(prevWBS,".","`",1))-1)))+1))) -> 5.2 | B38: ACC | C38: IT Support | D38: =COUNTIFS(#REF!,$B38,#REF!,$B$36,#REF!,"ใช้งาน") -> #REF! | E38: =COUNTIFS(#REF!,$B38,#REF!,$B$36,#REF!,Dashboard!$E$7)+F38 -> 0 | F38: =D38-E38 -> 0 | H38: =IF(ISBLANK(G38)," - ",IF(I38=0,G38,G38+I38-1)) -> - | I38: 1 | J38: =E38*100%/D38 -> 0 | K38: =IF(OR(H38=0,G38=0)," - ",NETWORKDAYS(G38,H38)) -> -
A39: =IF(ISERROR(VALUE(SUBSTITUTE(prevWBS,".",""))),"0.1",IF(ISERROR(FIND("`",SUBSTITUTE(prevWBS,".","`",1))),prevWBS&".1",LEFT(prevWBS,FIND("`",SUBSTITUTE(prevWBS,".","`",1)))&IF(ISERROR(FIND("`",SUBSTITUTE(prevWBS,".","`",2))),VALUE(RIGHT(prevWBS,LEN(prevWBS)-FIND("`",SUBSTITUTE(prevWBS,".","`",1))))+1,VALUE(MID(prevWBS,FIND("`",SUBSTITUTE(prevWBS,".","`",1))+1,(FIND("`",SUBSTITUTE(prevWBS,".","`",2))-FIND("`",SUBSTITUTE(prevWBS,".","`",1))-1)))+1))) -> 5.3 | B39: EXP | C39: IT Support | D39: =COUNTIFS(#REF!,$B39,#REF!,$B$36,#REF!,"ใช้งาน") -> #REF! | E39: =COUNTIFS(#REF!,$B39,#REF!,$B$36,#REF!,Dashboard!$E$7)+F39 -> 0 | F39: =D39-E39 -> 0 | H39: =IF(ISBLANK(G39)," - ",IF(I39=0,G39,G39+I39-1)) -> - | I39: 1 | J39: =E39*100%/D39 -> 0 | K39: =IF(OR(H39=0,G39=0)," - ",NETWORKDAYS(G39,H39)) -> -
A40: =IF(ISERROR(VALUE(SUBSTITUTE(prevWBS,".",""))),"1",IF(ISERROR(FIND("`",SUBSTITUTE(prevWBS,".","`",1))),TEXT(VALUE(prevWBS)+1,"#"),TEXT(VALUE(LEFT(prevWBS,FIND("`",SUBSTITUTE(prevWBS,".","`",1))-1))+1,"#"))) -> 6 | B40: TRRP | D40: =SUM(D41:D42) -> #REF! | E40: =SUM(E41:E42) -> #REF! | F40: =SUM(F41:F42) -> 0 | H40: =IF(ISBLANK(G40)," - ",IF(I40=0,G40,G40+I40-1)) -> - | K40: =IF(OR(H40=0,G40=0)," - ",NETWORKDAYS(G40,H40)) -> -
A41: =IF(ISERROR(VALUE(SUBSTITUTE(prevWBS,".",""))),"0.1",IF(ISERROR(FIND("`",SUBSTITUTE(prevWBS,".","`",1))),prevWBS&".1",LEFT(prevWBS,FIND("`",SUBSTITUTE(prevWBS,".","`",1)))&IF(ISERROR(FIND("`",SUBSTITUTE(prevWBS,".","`",2))),VALUE(RIGHT(prevWBS,LEN(prevWBS)-FIND("`",SUBSTITUTE(prevWBS,".","`",1))))+1,VALUE(MID(prevWBS,FIND("`",SUBSTITUTE(prevWBS,".","`",1))+1,(FIND("`",SUBSTITUTE(prevWBS,".","`",2))-FIND("`",SUBSTITUTE(prevWBS,".","`",1))-1)))+1))) -> 6.1 | B41: BUI | C41: IT Support | D41: =COUNTIFS(#REF!,$B41,#REF!,$B$40,#REF!,"ใช้งาน") -> #REF! | E41: =COUNTIFS(#REF!,$B41,#REF!,$B$40,#REF!,Dashboard!$E$7)+F41 -> #REF! | H41: =IF(ISBLANK(G41)," - ",IF(I41=0,G41,G41+I41-1)) -> - | I41: 1 | J41: =E41*100%/D41 -> #REF! | K41: =IF(OR(H41=0,G41=0)," - ",NETWORKDAYS(G41,H41)) -> -
...
